Workbook

Sheet Articles
A1: Réf | B1: Désignation | C1: Prix d'achat | D1: Stock initial | E1: Prix de vente
A2: LYK001 | B2: BABY BELLO ENS VIOLET 02P | C2: 3500 | D2: 1 | E2: 6500
A3: LYK002 | B3: BABY BELLO GREN CHAPEAU/MOUFLE | C3: 3000 | D3: 10 | E3: 6000
A4: LYK003 | B4: BABY F CHAPEAUX 01 PONPON | C4: 500 | D4: 5 | E4: 1000
A5: LYK004 | B5: BABY F CHAPEAUX 02 PONPONS | C5: 650 | D5: 18 | E5: 1300
A6: LYK005 | B6: BABYBUU ROBE | C6: 2828 | D6: 12 | E6: 5656
A7: LYK006 | B7: BABYGO ENS 02P MARRON GARCON | C7: 2793 | D7: 4 | E7: 5586
A8: LYK007 | B8: BABYGO ENS 02PROSE FILLE | C8: 3339 | D8: 4 | E8: 6678
A9: LYK008 | B9: BABYGO ENS JOGGING VERT 02P | C9: 3250 | D9: 2 | E9: 6500
A10: LYK009 | B10: BABYHI ENS JAUNE 03P | C10: 3750 | D10: 1 | E10: 7500
A11: LYK010 | B11: BB CHERI BABY F ENS 02P | C11: 4500 | D11: 2 | E11: 9000
A12: LYK011 | B12: BB CHERI BABY F ENS02P ROSE | C12: 3500 | D12: 4 | E12: 7000
A13: LYK012 | B13: BB CHERI BABY F GREN | C13: 3950 | D13: 4 | E13: 7900
... A169: LYK169 | B169: SERVIETTES PM | C169: 2200 | D169: 8 | E169: 3000

Sheet Ventes
A1: Date | B1: Réf | C1: Quantité | D1: Prix unité (réel) | E1: Prix total | F1: Marge unitaire | G1: Marge totale
A2: 45748 | B2: LYK017 | C2: 10 | D2: 1500 | E2: =C2*D2 -> 15000 | F2: =D2 - VLOOKUP(B2,Articles!A:D,3,FALSE) -> 750 | G2: =F2 * C2 -> 7500
A3: 45748 | B3: LYK070 | C3: 1 | D3: 2000 | E3: =C3*D3 -> 2000 | F3: =D3 - VLOOKUP(B3,Articles!A:D,3,FALSE) -> 500 | G3: =F3 * C3 -> 500
A4: 45748 | B4: LYK020 | C4: 3 | D4: 1000 | E4: =C4*D4 -> 3000 | F4: =D4 - VLOOKUP(B4,Articles!A:D,3,FALSE) -> 546.67 | G4: =F4 * C4 -> 1640.01
A5: 45748 | B5: LYK121 | C5: 2 | D5: 9500 | E5: =C5*D5 -> 19000 | F5: =D5 - VLOOKUP(B5,Articles!A:D,3,FALSE) -> 5125 | G5: =F5 * C5 -> 10250
A6: 45748 | B6: LYK021 | C6: 5 | D6: 2000 | E6: =C6*D6 -> 10000 | F6: =D6 - VLOOKUP(B6,Articles!A:D,3,FALSE) -> 1358.5 | G6: =F6 * C6 -> 6792.5
A7: 45748 | B7: LYK031 | C7: 1 | D7: 8500 | E7: =C7*D7 -> 8500 | F7: =D7 - VLOOKUP(B7,Articles!A:D,3,FALSE) -> 4699 | G7: =F7 * C7 -> 4699
A8: 45748 | B8: LYK059 | C8: 2 | D8: 6500 | E8: =C8*D8 -> 13000 | F8: =D8 - VLOOKUP(B8,Articles!A:D,3,FALSE) -> 3336 | G8: =F8 * C8 -> 6672
A9: 45748 | B9: LYK061 | C9: 1 | D9: 8500 | E9: =C9*D9 -> 8500 | F9: =D9 - VLOOKUP(B9,Articles!A:D,3,FALSE) -> 4468 | G9: =F9 * C9 -> 4468
A10: 45748 | B10: LYK153 | C10: 1 | D10: 8500 | E10: =C10*D10 -> 8500 | F10: =D10 - VLOOKUP(B10,Articles!A:D,3,FALSE) -> 3999 | G10: =F10 * C10 -> 3999
A11: 45748 | B11: LYK082 | C11: 2 | D11: 1000 | E11: =C11*D11 -> 2000 | F11: =D11 - VLOOKUP(B11,Articles!A:D,3,FALSE) -> 500 | G11: =F11 * C11 -> 1000
A12: 45748 | B12: LYK123 | C12: 1 | D12: 6500 | E12: =C12*D12 -> 6500 | F12: =D12 - VLOOKUP(B12,Articles!A:D,3,FALSE) -> 3735 | G12: =F12 * C12 -> 3735
A13: 45749 | B13: LYK140 | C13: 3 | D13: 3200 | E13: =C13*D13 -> 9600 | F13: =D13 - VLOOKUP(B13,Articles!A:D,3,FALSE) -> 1693 | G13: =F13 * C13 -> 5079
... A25: 45749 | B25: LYK094 | C25: 2 | D25: 2000 | E25: =C25*D25 -> 4000 | F25: =D25 - VLOOKUP(B25,Articles!A:D,3,FALSE) -> 1160 | G25: =F25 * C25 -> 2320
B26: LYK125 | C26: 1 | D26: 5000 | E26: =C26*D26 -> 5000 | F26: =D26 - VLOOKUP(B26,Articles!A:D,3,FALSE) -> 2725 | G26: =F26 * C26 -> 2725
B27: LYK141 | C27: 1 | D27: 2000 | E27: =C27*D27 -> 2000 | F27: =D27 - VLOOKUP(B27,Articles!A:D,3,FALSE) -> 1000 | G27: =F27 * C27 -> 1000
B28: LYK123 | C28: 1 | D28: 6500 | E28: =C28*D28 -> 6500 | F28: =D28 - VLOOKUP(B28,Articles!A:D,3,FALSE) -> 3735 | G28: =F28 * C28 -> 3735
B29: LYK161 | C29: 6 | D29: 334 | E29: =C29*D29 -> 2004 | F29: =D29 - VLOOKUP(B29,Articles!A:D,3,FALSE) -> 167 | G29: =F29 * C29 -> 1002
B30: LYK162 | C30: 1 | D30: 5000 | E30: =C30*D30 -> 5000 | F30: =D30 - VLOOKUP(B30,Articles!A:D,3,FALSE) -> 500 | G30: =F30 * C30 -> 500
B31: LYK163 | C31: 1 | D31: 3500 | E31: =C31*D31 -> 3500 | F31: =D31 - VLOOKUP(B31,Articles!A:D,3,FALSE) -> 1000 | G31: =F31 * C31 -> 1000
B32: LYK025 | C32: 1 | D32: 600 | E32: =C32*D32 -> 600 | F32: =D32 - VLOOKUP(B32,Articles!A:D,3,FALSE) -> 321.5 | G32: =F32 * C32 -> 321.5
B33: LYK121 | C33: 1 | D33: 8500 | E33: =C33*D33 -> 8500 | F33: =D33 - VLOOKUP(B33,Articles!A:D,3,FALSE) -> 4125 | G33: =F33 * C33 -> 4125
B34: LYK020 | C34: 1 | D34: 1000 | E34: =C34*D34 -> 1000 | F34: =D34 - VLOOKUP(B34,Articles!A:D,3,FALSE) -> 546.67 | G34: =F34 * C34 -> 546.67
B35: LYK028 | C35: 1 | D35: 3500 | E35: =C35*D35 -> 3500 | F35: =D35 - VLOOKUP(B35,Articles!A:D,3,FALSE) -> 1750 | G35: =F35 * C35 -> 1750
B36: LYK110 | C36: 1 | D36: 5500 | E36: =C36*D36 -> 5500 | F36: =D36 - VLOOKUP(B36,Articles!A:D,3,FALSE) -> 2945 | G36: =F36 * C36 -> 2945
B37: LYK015 | C37: 1 | D37: 8000 | E37: =C37*D37 -> 8000 | F37: =D37 - VLOOKUP(B37,Articles!A:D,3,FALSE) -> 4260 | G37: =F37 * C37 -> 4260
... B53: LYK020 | C53: 12 | D53: 1000 | E53: =C53*D53 -> 12000 | F53: =D53 - VLOOKUP(B53,Articles!A:D,3,FALSE) -> 546.67 | G53: =F53 * C53 -> 6560.04
A54: 45750 | B54: LYK010 | C54: 1 | D54: 8500 | E54: =C54*D54 -> 8500 | F54: =D54 - VLOOKUP(B54,Articles!A:D,3,FALSE) -> 4000 | G54: =F54 * C54 -> 4000
A55: 45750 | B55: LYK059 | C55: 1 | D55: 6000 | E55: =C55*D55 -> 6000 | F55: =D55 - VLOOKUP(B55,Articles!A:D,3,FALSE) -> 2836 | G55: =F55 * C55 -> 2836
A56: 45750 | B56: LYK061 | C56: 1 | D56: 8500 | E56: =C56*D56 -> 8500 | F56: =D56 - VLOOKUP(B56,Articles!A:D,3,FALSE) -> 4468 | G56: =F56 * C56 -> 4468
A57: 45750 | B57: LYK152 | C57: 1 | D57: 6000 | E57: =C57*D57 -> 6000 | F57: =D57 - VLOOKUP(B57,Articles!A:D,3,FALSE) -> 3000 | G57: =F57 * C57 -> 3000
A58: 45750 | B58: LYK082 | C58: 1 | D58: 1500 | E58: =C58*D58 -> 1500 | F58: =D58 - VLOOKUP(B58,Articles!A:D,3,FALSE) -> 1000 | G58: =F58 * C58 -> 1000
A59: 45750 | B59: LYK021 | C59: 1 | D59: 2000 | E59: =C59*D59 -> 2000 | F59: =D59 - VLOOKUP(B59,Articles!A:D,3,FALSE) -> 1358.5 | G59: =F59 * C59 -> 1358.5
B60: LYK026 | C60: 1 | D60: 1500 | E60: =C60*D60 -> 1500 | F60: =D60 - VLOOKUP(B60,Articles!A:D,3,FALSE) -> 750 | G60: =F60 * C60 -> 750
B61: LYK121 | C61: 1 | D61: 8500 | E61: =C61*D61 -> 8500 | F61: =D61 - VLOOKUP(B61,Articles!A:D,3,FALSE) -> 4125 | G61: =F61 * C61 -> 4125
B62: LYK004 | C62: 2 | D62: 1500 | E62: =C62*D62 -> 3000 | F62: =D62 - VLOOKUP(B62,Articles!A:D,3,FALSE) -> 850 | G62: =F62 * C62 -> 1700
B63: LYK005 | C63: 1 | D63: 6000 | E63: =C63*D63 -> 6000 | F63: =D63 - VLOOKUP(B63,Articles!A:D,3,FALSE) -> 3172 | G63: =F63 * C63 -> 3172
B64: LYK059 | C64: 1 | D64: 6500 | E64: =C64*D64 -> 6500 | F64: =D64 - VLOOKUP(B64,Articles!A:D,3,FALSE) -> 3336 | G64: =F64 * C64 -> 3336
B65: LYK106 | C65: 1 | D65: 6000 | E65: =C65*D65 -> 6000 | F65: =D65 - VLOOKUP(B65,Articles!A:D,3,FALSE) -> 2955 | G65: =F65 * C65 -> 2955
B66: LYK124 | C66: 1 | D66: 5500 | E66: =C66*D66 -> 5500 | F66: =D66 - VLOOKUP(B66,Articles!A:D,3,FALSE) -> 2735 | G66: =F66 * C66 -> 2735
...

Sheet Résumé Stock
A1: Réf | B1: Désignation | C1: Stock initial | D1: Quantité vendue | E1: Stock actuel | F1: Total Ventes | G1: Total Marge
A2: LYK017 | B2: =VLOOKUP(A2,Articles!A:B,2,FALSE) -> BELLA BANDEAUX | C2: =VLOOKUP(A2,Articles!A:D,4,FALSE) -> 85 | D2: =SUMIFS(Ventes!C:C,Ventes!B:B,A2) -> 60 | E2: =C2-D2 -> 25 | F2: =SUMIFS(Ventes!D:D,Ventes!B:B,A2) -> 20500 | G2: =SUMIFS(Ventes!G:G,Ventes!B:B,A2) -> 43000
A3: LYK070 | B3: =VLOOKUP(A3,Articles!A:B,2,FALSE) -> MC BARBO CM | C3: =VLOOKUP(A3,Articles!A:D,4,FALSE) -> 17 | D3: =SUMIFS(Ventes!C:C,Ventes!B:B,A3) -> 5 | E3: =C3-D3 -> 12 | F3: =SUMIFS(Ventes!D:D,Ventes!B:B,A3) -> 6000 | G3: =SUMIFS(Ventes!G:G,Ventes!B:B,A3) -> 2500
A4: LYK020 | B4: =VLOOKUP(A4,Articles!A:B,2,FALSE) -> BELLA CHAUSSETTE BALLERINE | C4: =VLOOKUP(A4,Articles!A:D,4,FALSE) -> 60 | D4: =SUMIFS(Ventes!C:C,Ventes!B:B,A4) -> 53 | E4: =C4-D4 -> 7 | F4: =SUMIFS(Ventes!D:D,Ventes!B:B,A4) -> 12000 | G4: =SUMIFS(Ventes!G:G,Ventes!B:B,A4) -> 28973.51
A5: LYK121 | B5: =VLOOKUP(A5,Articles!A:B,2,FALSE) -> MURAT ROBE CŒUR | C5: =VLOOKUP(A5,Articles!A:D,4,FALSE) -> 10 | D5: =SUMIFS(Ventes!C:C,Ventes!B:B,A5) -> 9 | E5: =C5-D5 -> 1 | F5: =SUMIFS(Ventes!D:D,Ventes!B:B,A5) -> 63000 | G5: =SUMIFS(Ventes!G:G,Ventes!B:B,A5) -> 42125
A6: LYK021 | B6: =VLOOKUP(A6,Articles!A:B,2,FALSE) -> BELLA CHAUSSETTE COLLANT NŒUD | C6: =VLOOKUP(A6,Articles!A:D,4,FALSE) -> 71 | D6: =SUMIFS(Ventes!C:C,Ventes!B:B,A6) -> 29 | E6: =C6-D6 -> 42 | F6: =SUMIFS(Ventes!D:D,Ventes!B:B,A6) -> 19000 | G6: =SUMIFS(Ventes!G:G,Ventes!B:B,A6) -> 34396.5
A7: LYK031 | B7: =VLOOKUP(A7,Articles!A:B,2,FALSE) -> COSAY ENS 03P GROS CŒUR | C7: =VLOOKUP(A7,Articles!A:D,4,FALSE) -> 3 | D7: =SUMIFS(Ventes!C:C,Ventes!B:B,A7) -> 3 | E7: =C7-D7 -> 0 | F7: =SUMIFS(Ventes!D:D,Ventes!B:B,A7) -> 24000 | G7: =SUMIFS(Ventes!G:G,Ventes!B:B,A7) -> 12597
A8: LYK059 | B8: =VLOOKUP(A8,Articles!A:B,2,FALSE) -> KIDEX ROBE CHAPEAU PAILLE | C8: =VLOOKUP(A8,Articles!A:D,4,FALSE) -> 16 | D8: =SUMIFS(Ventes!C:C,Ventes!B:B,A8) -> 15 | E8: =C8-D8 -> 1 | F8: =SUMIFS(Ventes!D:D,Ventes!B:B,A8) -> 73500 | G8: =SUMIFS(Ventes!G:G,Ventes!B:B,A8) -> 45040
A9: LYK061 | B9: =VLOOKUP(A9,Articles!A:B,2,FALSE) -> KITY SALOPETTE | C9: =VLOOKUP(A9,Articles!A:D,4,FALSE) -> 6 | D9: =SUMIFS(Ventes!C:C,Ventes!B:B,A9) -> 6 | E9: =C9-D9 -> 0 | F9: =SUMIFS(Ventes!D:D,Ventes!B:B,A9) -> 48500 | G9: =SUMIFS(Ventes!G:G,Ventes!B:B,A9) -> 24308
A10: LYK153 | B10: =VLOOKUP(A10,Articles!A:B,2,FALSE) -> TIMO ROBE FLEURI ROSE | C10: =VLOOKUP(A10,Articles!A:D,4,FALSE) -> 4 | D10: =SUMIFS(Ventes!C:C,Ventes!B:B,A10) -> 4 | E10: =C10-D10 -> 0 | F10: =SUMIFS(Ventes!D:D,Ventes!B:B,A10) -> 26500 | G10: =SUMIFS(Ventes!G:G,Ventes!B:B,A10) -> 17496
A11: LYK082 | B11: =VLOOKUP(A11,Articles!A:B,2,FALSE) -> MC COLLANT | C11: =VLOOKUP(A11,Articles!A:D,4,FALSE) -> 4 | D11: =SUMIFS(Ventes!C:C,Ventes!B:B,A11) -> 8 | E11: =C11-D11 -> -4 | F11: =SUMIFS(Ventes!D:D,Ventes!B:B,A11) -> 5500 | G11: =SUMIFS(Ventes!G:G,Ventes!B:B,A11) -> 4500
A12: LYK123 | B12: =VLOOKUP(A12,Articles!A:B,2,FALSE) -> MURAT ROBE JEAN DENTELLE HB | C12: =VLOOKUP(A12,Articles!A:D,4,FALSE) -> 4 | D12: =SUMIFS(Ventes!C:C,Ventes!B:B,A12) -> 4 | E12: =C12-D12 -> 0 | F12: =SUMIFS(Ventes!D:D,Ventes!B:B,A12) -> 19000 | G12: =SUMIFS(Ventes!G:G,Ventes!B:B,A12) -> 13940
A13: LYK140 | B13: =VLOOKUP(A13,Articles!A:B,2,FALSE) -> NAY GREN SIMPLES | C13: =VLOOKUP(A13,Articles!A:D,4,FALSE) -> 78 | D13: =SUMIFS(Ventes!C:C,Ventes!B:B,A13) -> 28 | E13: =C13-D13 -> 50 | F13: =SUMIFS(Ventes!D:D,Ventes!B:B,A13) -> 28400 | G13: =SUMIFS(Ventes!G:G,Ventes!B:B,A13) -> 44604
... A208: LYK161 | B208: =VLOOKUP(A208,Articles!A:B,2,FALSE) -> TURQUIE CHAUSSETTES | C208: =VLOOKUP(A208,Articles!A:D,4,FALSE) -> 20 | D208: =SUMIFS(Ventes!C:C,Ventes!B:B,A208) -> 15 | E208: =C208-D208 -> 5 | F208: =SUMIFS(Ventes!D:D,Ventes!B:B,A208) -> 1002 | G208: =SUMIFS(Ventes!G:G,Ventes!B:B,A208) -> 2505
B209: =VLOOKUP(A209,Articles!A:B,2,FALSE) -> #N/A | C209: =VLOOKUP(A209,Articles!A:D,4,FALSE) -> #N/A | D209: =SUMIFS(Ventes!C:C,Ventes!B:B,A209) -> 0 | E209: =C209-D209 -> #N/A | F209: =SUMIFS(Ventes!D:D,Ventes!B:B,A209) -> 0 | G209: =SUMIFS(Ventes!G:G,Ventes!B:B,A209) -> 0
B210: =VLOOKUP(A210,Articles!A:B,2,FALSE) -> #N/A | C210: =VLOOKUP(A210,Articles!A:D,4,FALSE) -> #N/A | D210: =SUMIFS(Ventes!C:C,Ventes!B:B,A210) -> 0 | E210: =C210-D210 -> #N/A | F210: =SUMIFS(Ventes!D:D,Ventes!B:B,A210) -> 0 | G210: =SUMIFS(Ventes!G:G,Ventes!B:B,A210) -> 0
B211: =VLOOKUP(A211,Articles!A:B,2,FALSE) -> #N/A | C211: =VLOOKUP(A211,Articles!A:D,4,FALSE) -> #N/A | D211: =SUMIFS(Ventes!C:C,Ventes!B:B,A211) -> 0 | E211: =C211-D211 -> #N/A | F211: =SUMIFS(Ventes!D:D,Ventes!B:B,A211) -> 0 | G211: =SUMIFS(Ventes!G:G,Ventes!B:B,A211) -> 0
B212: =VLOOKUP(A212,Articles!A:B,2,FALSE) -> #N/A | C212: =VLOOKUP(A212,Articles!A:D,4,FALSE) -> #N/A | D212: =SUMIFS(Ventes!C:C,Ventes!B:B,A212) -> 0 | E212: =C212-D212 -> #N/A | F212: =SUMIFS(Ventes!D:D,Ventes!B:B,A212) -> 0 | G212: =SUMIFS(Ventes!G:G,Ventes!B:B,A212) -> 0
B213: =VLOOKUP(A213,Articles!A:B,2,FALSE) -> #N/A | C213: =VLOOKUP(A213,Articles!A:D,4,FALSE) -> #N/A | D213: =SUMIFS(Ventes!C:C,Ventes!B:B,A213) -> 0 | E213: =C213-D213 -> #N/A | F213: =SUMIFS(Ventes!D:D,Ventes!B:B,A213) -> 0 | G213: =SUMIFS(Ventes!G:G,Ventes!B:B,A213) -> 0
B214: =VLOOKUP(A214,Articles!A:B,2,FALSE) -> #N/A | C214: =VLOOKUP(A214,Articles!A:D,4,FALSE) -> #N/A | D214: =SUMIFS(Ventes!C:C,Ventes!B:B,A214) -> 0 | E214: =C214-D214 -> #N/A | F214: =SUMIFS(Ventes!D:D,Ventes!B:B,A214) -> 0 | G214: =SUMIFS(Ventes!G:G,Ventes!B:B,A214) -> 0
B215: =VLOOKUP(A215,Articles!A:B,2,FALSE) -> #N/A | C215: =VLOOKUP(A215,Articles!A:D,4,FALSE) -> #N/A | D215: =SUMIFS(Ventes!C:C,Ventes!B:B,A215) -> 0 | E215: =C215-D215 -> #N/A | F215: =SUMIFS(Ventes!D:D,Ventes!B:B,A215) -> 0 | G215: =SUMIFS(Ventes!G:G,Ventes!B:B,A215) -> 0
B216: =VLOOKUP(A216,Articles!A:B,2,FALSE) -> #N/A | C216: =VLOOKUP(A216,Articles!A:D,4,FALSE) -> #N/A | D216: =SUMIFS(Ventes!C:C,Ventes!B:B,A216) -> 0 | E216: =C216-D216 -> #N/A | F216: =SUMIFS(Ventes!D:D,Ventes!B:B,A216) -> 0 | G216: =SUMIFS(Ventes!G:G,Ventes!B:B,A216) -> 0
